Workbook

Sheet KPI_Summary
A1: SPCKI sample KPI results (calculated live from the data sheets)
A2: Period: 2026-09-15 to 2026-09-28. All figures are formulas, so they update when the data changes.
A3: KPI | B3: Value | C3: How it is calculated
A4: OVERVIEW
A5: Registered households | B5: =COUNTA(Households!$A$2:$A$17) -> 16 | C5: Households in the register
A6: Active households | B6: =SUMPRODUCT(--(Households!$J$2:$J$17>0)) -> 16 | C6: Households with at least one attended session
A7: Participation rate | B7: =B6/B5 -> 1 | C7: Active ÷ Registered
A8: Slots scheduled | B8: =COUNTA(Slots!$A$2:$A$85) -> 84 | C8: All slots in the period
A9: Slots used (attended or swapped) | B9: =COUNTIF(Slots!$H$2:$H$85,"Attended")+COUNTIF(Slots!$H$2:$H$85,"Swapped") -> 79 | C9: Slots where a household cooked
A10: Slot utilisation | B10: =B9/B8 -> 0.94047619 | C10: Used ÷ Scheduled
A11: COOKING
A12: Total sessions | B12: =COUNTA(Cooking_Sessions!$A$2:$A$80) -> 79
A13: Completed sessions | B13: =COUNTIF(Cooking_Sessions!$M$2:$M$80,"Yes") -> 78
A14: Session completion rate | B14: =B13/B12 -> 0.98734177 | C14: Completed ÷ Total
A15: Average cooking time (min, completed) | B15: =AVERAGEIFS(Cooking_Sessions!$I$2:$I$80,Cooking_Sessions!$M$2:$M$80,"Yes") -> 59.423077 | C15: Total cooking time ÷ Completed sessions
A16: Average minutes per person | B16: =AVERAGEIFS(Cooking_Sessions!$U$2:$U$80,Cooking_Sessions!$M$2:$M$80,"Yes") -> 12.914103 | C16: Cooking time ÷ persons cooked for
A17: Cleaning compliance | B17: =COUNTIF(Cooking_Sessions!$N$2:$N$80,"Yes")/B12 -> 0.91139241 | C17: Cleaned ÷ Total sessions
A18: Waiting issue rate | B18: =COUNTIF(Cooking_Sessions!$O$2:$O$80,"Yes")/B12 -> 0.10126582 | C18: Sessions with waiting issue ÷ Total
A19: Technical fault rate (sessions) | B19: =COUNTIF(Cooking_Sessions!$Q$2:$Q$80,"Yes")/B12 -> 0.13924051 | C19: Sessions with a problem ÷ Total
A20: TECHNICAL
A21: System uptime | B21: =1-SUM(Daily_Technical!$H$2:$H$15)/(Config!$B$7*COUNTA(Daily_Technical!$A$2:$A$15)) -> 0.97802198 | C21: (Scheduled hours − Downtime) ÷ Scheduled hours
A22: Average downtime per day (h) | B22: =SUM(Daily_Technical!$H$2:$H$15)/COUNTA(Daily_Technical!$A$2:$A$15) -> 0.28571429 | C22: Total downtime ÷ Days logged
A23: Technical faults (days total) | B23: =SUM(Daily_Technical!$G$2:$G$15) -> 4
A24: Safety incidents | B24: =COUNTIF(Daily_Technical!$I$2:$I$15,"Yes") -> 1
A25: Generator running hours | B25: =SUM(Generator_Log!$E$2:$E$7) -> 25.5
A26: Generator fuel used (L) | B26: =SUM(Generator_Log!$I$2:$I$7) -> 33.3 | C26: Start + Re-fuel − End
A27: SOLAR AND ENERGY
A28: Solar produced (kWh) | B28: =SUM(Daily_Technical!$C$2:$C$15) -> 96.1
A29: Expected solar (kWh) | B29: =SUM(Daily_Technical!$L$2:$L$15) -> 110.06 | C29: Panel kWp × Peak sun hours × Weather factor × Performance ratio
A30: Efficiency | B30: =B28/B29 -> 0.87316009 | C30: Actual ÷ Expected
A31: Energy consumed (kWh) | B31: =SUM(Daily_Technical!$K$2:$K$15) -> 53.13 | C31: Cooking energy from solar and battery (generator slots excluded; lights and fans not included)
A32: Wasted energy (kWh) | B32: =SUM(Daily_Technical!$O$2:$O$15) -> 35.47 | C32: Generated − Consumed − Battery change
A33: Wasted share of solar | B33: =B32/B28 -> 0.36909469
A34: Downtime loss (kWh) | B34: =SUM(Daily_Technical!$Q$2:$Q$15) -> 0.71 | C34: Expected hourly output × Downtime hours
A35: HOUSEHOLD FEEDBACK
A36: Average overall satisfaction (1-5) | B36: =AVERAGE(Monthly_Feedback!$I$2:$I$17) -> 3.9375
A37: Average safety (1-5) | B37: =AVERAGE(Monthly_Feedback!$F$2:$F$17) -> 4.4375
A38: Average waiting experience (1-5) | B38: =AVERAGE(Monthly_Feedback!$H$2:$H$17) -> 3.5
A39: Willing to continue | B39: =COUNTIF(Monthly_Feedback!$O$2:$O$17,"Yes")/COUNTA(Monthly_Feedback!$O$2:$O$17) -> 0.875
A40: Baseline monthly fuel cost (BDT) | B40: =SUM(Households!$F$2:$F$17) -> 17250 | C40: Before the pilot, all households
...

Sheet README
A1: SPCKI Sample Data Set
A2: Example data showing how the monitoring platform works: 1 kitchen, 16 households, 14 days (15 to 28 September 2026).
A4: IMPORTANT: this data is simulated for demonstration. It is not real field data. Panel size, battery size and the weather factors are assumptions (see Config).
A6: How the data flows
A7: 1. Config, Weather_Factors, Appliances, Dishes, Problem_Categories, Users and Households are set up once by the administrator.
A8: 2. Slots: every day has 6 cooking slots with a power source. Households are assigned in rotation. Status: Attended, Missed, Cancelled or Swapped.
A9: 3. Cooking_Sessions (+ Session_Dishes): one row for each slot where a household cooked. Duration, energy, minutes per person and size band are calculated.
A10: 4. Daily_Technical: one row per day (solar, battery, faults, downtime, weather). Expected solar, efficiency and wasted energy are calculated.
A11: 5. Generator_Log: one row per generator day. Fuel used is calculated.
A12: 6. Monthly_Feedback: one survey row per household (ratings, fuel spend, family size, time enough).
A13: 7. KPI_Summary: every KPI is a live formula over the sheets above. Audit_Log shows what the system records about who did what.
A15: Colour legend
... A22: Wasted energy is highest on sunny days when the battery is full; generator slots appear on cloudy, rainy and stormy days.

Sheet Config
A1: Setting | B1: Value | C1: Note
A2: kitchen_name | B2: Kitchen A (pilot) | C2: Sample kitchen used for this example
A3: pv_capacity_kwp | B3: 4 | C3: Installed solar panel capacity. ASSUMPTION: replace with the real size
A4: battery_capacity_kwh | B4: 10 | C4: Usable battery capacity. ASSUMPTION: replace with the real size
A5: performance_ratio | B5: 0.75 | C5: Normal system losses (heat, wiring, inverter, dust). Typical 0.70 to 0.80
A6: peak_sun_hours | B6: 4.5 | C6: Average full-sun hours per day. ASSUMPTION for Bangladesh, about 4.5 to 5
A7: scheduled_hours_per_day | B7: 13 | C7: Hours the kitchen is meant to run (06:00 to 19:00)
A8: max_households | B8: 16 | C8: Households served by this kitchen
A9: slots_per_day | B9: 6 | C9: Cooking turns per day
A10: cooking_duty_factor | B10: 0.6 | C10: Share of cooking time an appliance draws full power. ASSUMPTION
A11: productive_sun_hours | B11: 10 | C11: Hours used to turn daily expected output into hourly output for downtime loss. ASSUMPTION
A12: period_start | B12: 46280 | C12: First day of the sample data
A13: period_end | B13: 46293 | C13: Last day of the sample data

Sheet Weather_Factors
A1: Weather | B1: Factor (share of a sunny day)
A2: Sunny | B2: 1
A3: Partly cloudy | B3: 0.65
A4: Cloudy | B4: 0.35
A5: Rainy | B5: 0.2
A6: Stormy | B6: 0.1

Sheet Appliances
A1: ID | B1: Appliance | C1: Power (kW)
A2: 1 | B2: Induction cooktop | C2: 2
A3: 2 | B3: Electric pressure cooker | C3: 1
A4: 3 | B4: Rice cooker | C4: 0.7

Sheet Dishes
A1: ID | B1: Dish
A2: 1 | B2: Rice
A3: 2 | B3: Dal
A4: 3 | B4: Vegetables
A5: 4 | B5: Fish
A6: 5 | B6: Meat
A7: 6 | B7: Curry
A8: 7 | B8: Khichuri
A9: 8 | B9: Other

Sheet Problem_Categories
A1: ID | B1: Kind | C1: Name
A2: 1 | B2: Waiting | C2: No free slot
A3: 2 | B3: Waiting | C3: Appliance busy
A4: 3 | B4: Waiting | C4: Late start
A5: 4 | B5: Technical | C5: Power cut
A6: 5 | B6: Technical | C6: Appliance fault
A7: 6 | B7: Technical | C7: Low battery
A8: 7 | B8: Technical | C8: Other

Sheet Users
A1: ID | B1: Username | C1: Full name (sample) | D1: Role | E1: Kitchen | F1: Status
A2: 1 | B2: admin01 | C2: Nasrin Akter | D2: Admin | E2: Kitchen A | F2: Active
A3: 2 | B3: proj01 | C3: Md. Karim | D3: Project | E3: Kitchen A | F3: Active
A4: 3 | B4: field01 | C4: Salma Begum | D4: Field | E4: Kitchen A | F4: Active
A5: 4 | B5: field02 | C5: Jamal Hossain | D5: Field | E5: Kitchen A | F5: Active
A6: 5 | B6: tech01 | C6: Rafiq Ahmed | D6: Technical | E6: Kitchen A | F6: Active
A7: 6 | B7: viewer01 | C7: Farhana Islam | D7: Viewer | E7: All kitchens | F7: Active

Sheet Households
A1: Household code | B1: Family size | C1: Children | D1: Adults | E1: Baseline fuel type | F1: Baseline monthly fuel cost (BDT) | G1: Status | H1: Kitchen | I1: Joined | J1: Sessions attended (calc) | K1: Slots assigned (calc)
A2: HH-01 | B2: 4 | C2: 2 | D2: 2 | E2: Firewood | F2: 900 | G2: Active | H2: Kitchen A | I2: 46266 | J2: =COUNTIF(Cooking_Sessions!$D$2:$D$80,A2) -> 6 | K2: =COUNTIF(Slots!$G$2:$G$85,A2) -> 6
A3: HH-02 | B3: 6 | C3: 4 | D3: 2 | E3: LPG | F3: 1400 | G3: Active | H3: Kitchen A | I3: 46266 | J3: =COUNTIF(Cooking_Sessions!$D$2:$D$80,A3) -> 5 | K3: =COUNTIF(Slots!$G$2:$G$85,A3) -> 6
A4: HH-03 | B4: 3 | C4: 1 | D4: 2 | E4: Firewood | F4: 600 | G4: Active | H4: Kitchen A | I4: 46266 | J4: =COUNTIF(Cooking_Sessions!$D$2:$D$80,A4) -> 5 | K4: =COUNTIF(Slots!$G$2:$G$85,A4) -> 6
A5: HH-04 | B5: 5 | C5: 3 | D5: 2 | E5: Firewood | F5: 1100 | G5: Active | H5: Kitchen A | I5: 46266 | J5: =COUNTIF(Cooking_Sessions!$D$2:$D$80,A5) -> 3 | K5: =COUNTIF(Slots!$G$2:$G$85,A5) -> 3
A6: HH-05 | B6: 7 | C6: 5 | D6: 2 | E6: LPG | F6: 1700 | G6: Active | H6: Kitchen A | I6: 46266 | J6: =COUNTIF(Cooking_Sessions!$D$2:$D$80,A6) -> 5 | K6: =COUNTIF(Slots!$G$2:$G$85,A6) -> 5
A7: HH-06 | B7: 5 | C7: 3 | D7: 2 | E7: Firewood | F7: 1000 | G7: Active | H7: Kitchen A | I7: 46266 | J7: =COUNTIF(Cooking_Sessions!$D$2:$D$80,A7) -> 5 | K7: =COUNTIF(Slots!$G$2:$G$85,A7) -> 5
A8: HH-07 | B8: 8 | C8: 5 | D8: 3 | E8: Firewood | F8: 1800 | G8: Active | H8: Kitchen A | I8: 46266 | J8: =COUNTIF(Cooking_Sessions!$D$2:$D$80,A8) -> 6 | K8: =COUNTIF(Slots!$G$2:$G$85,A8) -> 6
A9: HH-08 | B9: 4 | C9: 2 | D9: 2 | E9: LPG | F9: 800 | G9: Active | H9: Kitchen A | I9: 46266 | J9: =COUNTIF(Cooking_Sessions!$D$2:$D$80,A9) -> 6 | K9: =COUNTIF(Slots!$G$2:$G$85,A9) -> 6
A10: HH-09 | B10: 6 | C10: 4 | D10: 2 | E10: Firewood | F10: 1200 | G10: Active | H10: Kitchen A | I10: 46266 | J10: =COUNTIF(Cooking_Sessions!$D$2:$D$80,A10) -> 6 | K10: =COUNTIF(Slots!$G$2:$G$85,A10) -> 6
A11: HH-10 | B11: 3 | C11: 2 | D11: 1 | E11: Firewood | F11: 500 | G11: Active | H11: Kitchen A | I11: 46266 | J11: =COUNTIF(Cooking_Sessions!$D$2:$D$80,A11) -> 4 | K11: =COUNTIF(Slots!$G$2:$G$85,A11) -> 4
A12: HH-11 | B12: 5 | C12: 3 | D12: 2 | E12: LPG | F12: 1000 | G12: Active | H12: Kitchen A | I12: 46266 | J12: =COUNTIF(Cooking_Sessions!$D$2:$D$80,A12) -> 6 | K12: =COUNTIF(Slots!$G$2:$G$85,A12) -> 6
A13: HH-12 | B13: 7 | C13: 5 | D13: 2 | E13: Firewood | F13: 1600 | G13: Active | H13: Kitchen A | I13: 46266 | J13: =COUNTIF(Cooking_Sessions!$D$2:$D$80,A13) -> 4 | K13: =COUNTIF(Slots!$G$2:$G$85,A13) -> 4
... A17: HH-16 | B17: 3 | C17: 1 | D17: 2 | E17: Firewood | F17: 550 | G17: Active | H17: Kitchen A | I17: 46266 | J17: =COUNTIF(Cooking_Sessions!$D$2:$D$80,A17) -> 5 | K17: =COUNTIF(Slots!$G$2:$G$85,A17) -> 5

Sheet Slots
A1: Slot ID | B1: Date | C1: Slot no. | D1: Start | E1: End | F1: Power source | G1: Household | H1: Status | I1: Note
A2: SL-0001 | B2: 46280 | C2: 1 | D2: 0.25 | E2: 0.33333333 | F2: Battery | G2: HH-01 | H2: Attended
A3: SL-0002 | B3: 46280 | C3: 2 | D3: 0.33333333 | E3: 0.41666667 | F3: Solar | G3: HH-02 | H3: Attended
A4: SL-0003 | B4: 46280 | C4: 3 | D4: 0.41666667 | E4: 0.5 | F4: Solar | G4: HH-03 | H4: Missed | I4: Household did not arrive
A5: SL-0004 | B5: 46280 | C5: 4 | D5: 0.5 | E5: 0.58333333 | F5: Solar | G5: HH-04 | H5: Attended
A6: SL-0005 | B6: 46280 | C6: 5 | D6: 0.58333333 | E6: 0.66666667 | F6: Generator | G6: HH-05 | H6: Attended
A7: SL-0006 | B7: 46280 | C7: 6 | D7: 0.6875 | E7: 0.77083333 | F7: Generator | G7: HH-06 | H7: Attended
A8: SL-0007 | B8: 46281 | C8: 1 | D8: 0.25 | E8: 0.33333333 | F8: Battery | G8: HH-07 | H8: Attended
A9: SL-0008 | B9: 46281 | C9: 2 | D9: 0.33333333 | E9: 0.41666667 | F9: Solar | G9: HH-08 | H9: Attended
A10: SL-0009 | B10: 46281 | C10: 3 | D10: 0.41666667 | E10: 0.5 | F10: Solar | G10: HH-09 | H10: Attended
A11: SL-0010 | B11: 46281 | C11: 4 | D11: 0.5 | E11: 0.58333333 | F11: Solar | G11: HH-10 | H11: Attended
A12: SL-0011 | B12: 46281 | C12: 5 | D12: 0.58333333 | E12: 0.66666667 | F12: Generator | G12: HH-11 | H12: Attended
A13: SL-0012 | B13: 46281 | C13: 6 | D13: 0.6875 | E13: 0.77083333 | F13: Generator | G13: HH-12 | H13: Attended
A14: SL-0013 | B14: 46282 | C14: 1 | D14: 0.25 | E14: 0.33333333 | F14: Battery | G14: HH-13 | H14: Attended
A15: SL-0014 | B15: 46282 | C15: 2 | D15: 0.33333333 | E15: 0.41666667 | F15: Solar | G15: HH-14 | H15: Attended
A16: SL-0015 | B16: 46282 | C16: 3 | D16: 0.41666667 | E16: 0.5 | F16: Solar | G16: HH-15 | H16: Attended
A17: SL-0016 | B17: 46282 | C17: 4 | D17: 0.5 | E17: 0.58333333 | F17: Solar | G17: HH-16 | H17: Attended
A18: SL-0017 | B18: 46282 | C18: 5 | D18: 0.58333333 | E18: 0.66666667 | F18: Solar | G18: HH-09 | H18: Swapped | I18: Swapped with HH-01
A19: SL-0018 | B19: 46282 | C19: 6 | D19: 0.6875 | E19: 0.77083333 | F19: Battery | G19: HH-02 | H19: Attended
A20: SL-0019 | B20: 46283 | C20: 1 | D20: 0.25 | E20: 0.33333333 | F20: Battery | G20: HH-03 | H20: Attended
A21: SL-0020 | B21: 46283 | C21: 2 | D21: 0.33333333 | E21: 0.41666667 | F21: Solar | G21: HH-04 | H21: Attended
A22: SL-0021 | B22: 46283 | C22: 3 | D22: 0.41666667 | E22: 0.5 | F22: Solar | G22: HH-05 | H22: Attended
A23: SL-0022 | B23: 46283 | C23: 4 | D23: 0.5 | E23: 0.58333333 | F23: Solar | G23: HH-06 | H23: Attended
A24: SL-0023 | B24: 46283 | C24: 5 | D24: 0.58333333 | E24: 0.66666667 | F24: Solar | G24: HH-07 | H24: Attended
A25: SL-0024 | B25: 46283 | C25: 6 | D25: 0.6875 | E25: 0.77083333 | F25: Battery | G25: HH-08 | H25: Attended
A26: SL-0025 | B26: 46284 | C26: 1 | D26: 0.25 | E26: 0.33333333 | F26: Battery | G26: HH-09 | H26: Attended
A27: SL-0026 | B27: 46284 | C27: 2 | D27: 0.33333333 | E27: 0.41666667 | F27: Solar | G27: HH-10 | H27: Attended
A28: SL-0027 | B28: 46284 | C28: 3 | D28: 0.41666667 | E28: 0.5 | F28: Solar | G28: HH-11 | H28: Attended
A29: SL-0028 | B29: 46284 | C29: 4 | D29: 0.5 | E29: 0.58333333 | F29: Solar | G29: HH-12 | H29: Attended
A30: SL-0029 | B30: 46284 | C30: 5 | D30: 0.58333333 | E30: 0.66666667 | F30: Solar | G30: HH-13 | H30: Attended
... A36: SL-0035 | B36: 46285 | C36: 5 | D36: 0.58333333 | E36: 0.66666667 | F36: Solar | G36: HH-03 | H36: Attended
A37: SL-0036 | B37: 46285 | C37: 6 | D37: 0.6875 | E37: 0.77083333 | F37: Battery | G37: HH-06 | H37: Swapped | I37: Swapped with HH-04
A38: SL-0037 | B38: 46286 | C38: 1 | D38: 0.25 | E38: 0.33333333 | F38: Battery | G38: HH-05 | H38: Attended
A39: SL-0038 | B39: 46286 | C39: 2 | D39: 0.33333333 | E39: 0.41666667 | F39: Solar | G39: HH-06 | H39: Attended
A40: SL-0039 | B40: 46286 | C40: 3 | D40: 0.41666667 | E40: 0.5 | F40: Solar | G40: HH-07 | H40: Attended
A41: SL-0040 | B41: 46286 | C41: 4 | D41: 0.5 | E41: 0.58333333 | F41: Solar | G41: HH-08 | H41: Attended
A42: SL-0041 | B42: 46286 | C42: 5 | D42: 0.58333333 | E42: 0.66666667 | F42: Generator | G42: HH-09 | H42: Attended
A43: SL-0042 | B43: 46286 | C43: 6 | D43: 0.6875 | E43: 0.77083333 | F43: Generator | G43: HH-10 | H43: Attended
A44: SL-0043 | B44: 46287 | C44: 1 | D44: 0.25 | E44: 0.33333333 | F44: Battery | G44: HH-11 | H44: Attended
A45: SL-0044 | B45: 46287 | C45: 2 | D45: 0.33333333 | E45: 0.41666667 | F45: Solar | G45: HH-12 | H45: Attended
...

Sheet Cooking_Sessions
A1: Session ID | B1: Date | C1: Slot ID | D1: Household | E1: Family size (calc) | F1: Persons cooked for | G1: Start | H1: End | I1: Duration, min (calc) | J1: Dishes | K1: Appliance | L1: Power source | M1: Cooking completed | N1: Cleaning completed | O1: Waiting issue | P1: Waiting reason | Q1: Technical problem | R1: Problem type | S1: Remarks | T1: Energy, kWh (calc) | U1: Minutes per person (calc) | V1: Size band (calc)
A2: CS-0001 | B2: 46280 | C2: SL-0001 | D2: HH-01 | E2: =INDEX(Households!$B$2:$B$17,MATCH(D2,Households!$A$2:$A$17,0)) -> 4 | F2: 4 | G2: 0.25 | H2: 0.28125 | I2: =ROUND((H2-G2)*1440,0) -> 45 | J2: Rice, Dal | K2: Electric pressure cooker | L2: Battery | M2: Yes | N2: Yes | O2: No | Q2: No | T2: =ROUND(INDEX(Appliances!$C$2:$C$4,MATCH(K2,Appliances!$B$2:$B$4,0))*I2/60*Config!$B$10,2) -> 0.45 | U2: =ROUND(I2/F2,1) -> 11.3 | V2: =IF(F2<=3,"1-3",IF(F2<=5,"4-5",IF(F2<=7,"6-7","8+"))) -> 4-5
A3: CS-0002 | B3: 46280 | C3: SL-0002 | D3: HH-02 | E3: =INDEX(Households!$B$2:$B$17,MATCH(D3,Households!$A$2:$A$17,0)) -> 6 | F3: 6 | G3: 0.34027778 | H3: 0.38541667 | I3: =ROUND((H3-G3)*1440,0) -> 65 | J3: Rice, Vegetables | K3: Induction cooktop | L3: Solar | M3: Yes | N3: Yes | O3: No | Q3: No | T3: =ROUND(INDEX(Appliances!$C$2:$C$4,MATCH(K3,Appliances!$B$2:$B$4,0))*I3/60*Config!$B$10,2) -> 1.3 | U3: =ROUND(I3/F3,1) -> 10.8 | V3: =IF(F3<=3,"1-3",IF(F3<=5,"4-5",IF(F3<=7,"6-7","8+"))) -> 6-7
A4: CS-0003 | B4: 46280 | C4: SL-0004 | D4: HH-04 | E4: =INDEX(Households!$B$2:$B$17,MATCH(D4,Households!$A$2:$A$17,0)) -> 5 | F4: 5 | G4: 0.50694444 | H4: 0.54513889 | I4: =ROUND((H4-G4)*1440,0) -> 55 | J4: Rice, Dal, Fish | K4: Electric pressure cooker | L4: Solar | M4: Yes | N4: Yes | O4: No | Q4: No | T4: =ROUND(INDEX(Appliances!$C$2:$C$4,MATCH(K4,Appliances!$B$2:$B$4,0))*I4/60*Config!$B$10,2) -> 0.55 | U4: =ROUND(I4/F4,1) -> 11 | V4: =IF(F4<=3,"1-3",IF(F4<=5,"4-5",IF(F4<=7,"6-7","8+"))) -> 4-5
A5: CS-0004 | B5: 46280 | C5: SL-0005 | D5: HH-05 | E5: =INDEX(Households!$B$2:$B$17,MATCH(D5,Households!$A$2:$A$17,0)) -> 7 | F5: 6 | G5: 0.58680556 | H5: 0.63194444 | I5: =ROUND((H5-G5)*1440,0) -> 65 | J5: Rice, Meat | K5: Electric pressure cooker | L5: Generator | M5: Yes | N5: Yes | O5: No | Q5: No | T5: =ROUND(INDEX(Appliances!$C$2:$C$4,MATCH(K5,Appliances!$B$2:$B$4,0))*I5/60*Config!$B$10,2) -> 0.65 | U5: =ROUND(I5/F5,1) -> 10.8 | V5: =IF(F5<=3,"1-3",IF(F5<=5,"4-5",IF(F5<=7,"6-7","8+"))) -> 6-7
A6: CS-0005 | B6: 46280 | C6: SL-0006 | D6: HH-06 | E6: =INDEX(Households!$B$2:$B$17,MATCH(D6,Households!$A$2:$A$17,0)) -> 5 | F6: 5 | G6: 0.69097222 | H6: 0.71875 | I6: =ROUND((H6-G6)*1440,0) -> 40 | J6: Rice, Dal | K6: Electric pressure cooker | L6: Generator | M6: Yes | N6: Yes | O6: No | Q6: No | T6: =ROUND(INDEX(Appliances!$C$2:$C$4,MATCH(K6,Appliances!$B$2:$B$4,0))*I6/60*Config!$B$10,2) -> 0.4 | U6: =ROUND(I6/F6,1) -> 8 | V6: =IF(F6<=3,"1-3",IF(F6<=5,"4-5",IF(F6<=7,"6-7","8+"))) -> 4-5
A7: CS-0006 | B7: 46281 | C7: SL-0007 | D7: HH-07 | E7: =INDEX(Households!$B$2:$B$17,MATCH(D7,Households!$A$2:$A$17,0)) -> 8 | F7: 8 | G7: 0.25347222 | H7: 0.32638889 | I7: =ROUND((H7-G7)*1440,0) -> 105 | J7: Rice, Dal, Meat | K7: Electric pressure cooker | L7: Battery | M7: Yes | N7: Yes | O7: No | Q7: No | S7: Needed more time for 8 persons | T7: =ROUND(INDEX(Appliances!$C$2:$C$4,MATCH(K7,Appliances!$B$2:$B$4,0))*I7/60*Config!$B$10,2) -> 1.05 | U7: =ROUND(I7/F7,1) -> 13.1 | V7: =IF(F7<=3,"1-3",IF(F7<=5,"4-5",IF(F7<=7,"6-7","8+"))) -> 8+
A8: CS-0007 | B8: 46281 | C8: SL-0008 | D8: HH-08 | E8: =INDEX(Households!$B$2:$B$17,MATCH(D8,Households!$A$2:$A$17,0)) -> 4 | F8: 4 | G8: 0.33333333 | H8: 0.37152778 | I8: =ROUND((H8-G8)*1440,0) -> 55 | J8: Khichuri | K8: Electric pressure cooker | L8: Solar | M8: Yes | N8: Yes | O8: No | Q8: Yes | R8: Power cut | T8: =ROUND(INDEX(Appliances!$C$2:$C$4,MATCH(K8,Appliances!$B$2:$B$4,0))*I8/60*Config!$B$10,2) -> 0.55 | U8: =ROUND(I8/F8,1) -> 13.8 | V8: =IF(F8<=3,"1-3",IF(F8<=5,"4-5",IF(F8<=7,"6-7","8+"))) -> 4-5
A9: CS-0008 | B9: 46281 | C9: SL-0009 | D9: HH-09 | E9: =INDEX(Households!$B$2:$B$17,MATCH(D9,Households!$A$2:$A$17,0)) -> 6 | F9: 6 | G9: 0.41666667 | H9: 0.44791667 | I9: =ROUND((H9-G9)*1440,0) -> 45 | J9: Rice, Dal | K9: Electric pressure cooker | L9: Solar | M9: Yes | N9: Yes | O9: No | Q9: No | T9: =ROUND(INDEX(Appliances!$C$2:$C$4,MATCH(K9,Appliances!$B$2:$B$4,0))*I9/60*Config!$B$10,2) -> 0.45 | U9: =ROUND(I9/F9,1) -> 7.5 | V9: =IF(F9<=3,"1-3",IF(F9<=5,"4-5",IF(F9<=7,"6-7","8+"))) -> 6-7
A10: CS-0009 | B10: 46281 | C10: SL-0010 | D10: HH-10 | E10: =INDEX(Households!$B$2:$B$17,MATCH(D10,Households!$A$2:$A$17,0)) -> 3 | F10: 3 | G10: 0.5 | H10: 0.53819444 | I10: =ROUND((H10-G10)*1440,0) -> 55 | J10: Rice, Dal, Vegetables | K10: Electric pressure cooker | L10: Solar | M10: Yes | N10: Yes | O10: No | Q10: No | T10: =ROUND(INDEX(Appliances!$C$2:$C$4,MATCH(K10,Appliances!$B$2:$B$4,0))*I10/60*Config!$B$10,2) -> 0.55 | U10: =ROUND(I10/F10,1) -> 18.3 | V10: =IF(F10<=3,"1-3",IF(F10<=5,"4-5",IF(F10<=7,"6-7","8+"))) -> 1-3
A11: CS-0010 | B11: 46281 | C11: SL-0011 | D11: HH-11 | E11: =INDEX(Households!$B$2:$B$17,MATCH(D11,Households!$A$2:$A$17,0)) -> 5 | F11: 5 | G11: 0.59027778 | H11: 0.62847222 | I11: =ROUND((H11-G11)*1440,0) -> 55 | J11: Rice, Dal, Vegetables | K11: Electric pressure cooker | L11: Generator | M11: Yes | N11: Yes | O11: Yes | P11: Late start | Q11: No | S11: Previous household finished late | T11: =ROUND(INDEX(Appliances!$C$2:$C$4,MATCH(K11,Appliances!$B$2:$B$4,0))*I11/60*Config!$B$10,2) -> 0.55 | U11: =ROUND(I11/F11,1) -> 11 | V11: =IF(F11<=3,"1-3",IF(F11<=5,"4-5",IF(F11<=7,"6-7","8+"))) -> 4-5
A12: CS-0011 | B12: 46281 | C12: SL-0012 | D12: HH-12 | E12: =INDEX(Households!$B$2:$B$17,MATCH(D12,Households!$A$2:$A$17,0)) -> 7 | F12: 7 | G12: 0.6875 | H12: 0.77083333 | I12: =ROUND((H12-G12)*1440,0) -> 120 | J12: Rice, Vegetables | K12: Induction cooktop | L12: Generator | M12: Yes | N12: Yes | O12: No | Q12: Yes | R12: Appliance fault | T12: =ROUND(INDEX(Appliances!$C$2:$C$4,MATCH(K12,Appliances!$B$2:$B$4,0))*I12/60*Config!$B$10,2) -> 2.4 | U12: =ROUND(I12/F12,1) -> 17.1 | V12: =IF(F12<=3,"1-3",IF(F12<=5,"4-5",IF(F12<=7,"6-7","8+"))) -> 6-7
A13: CS-0012 | B13: 46282 | C13: SL-0013 | D13: HH-13 | E13: =INDEX(Households!$B$2:$B$17,MATCH(D13,Households!$A$2:$A$17,0)) -> 4 | F13: 4 | G13: 0.25347222 | H13: 0.29513889 | I13: =ROUND((H13-G13)*1440,0) -> 60 | J13: Rice, Fish | K13: Induction cooktop | L13: Battery | M13: Yes | N13: No | O13: No | Q13: No | T13: =ROUND(INDEX(Appliances!$C$2:$C$4,MATCH(K13,Appliances!$B$2:$B$4,0))*I13/60*Config!$B$10,2) -> 1.2 | U13: =ROUND(I13/F13,1) -> 15 | V13: =IF(F13<=3,"1-3",IF(F13<=5,"4-5",IF(F13<=7,"6-7","8+"))) -> 4-5
A14: CS-0013 | B14: 46282 | C14: SL-0014 | D14: HH-14 | E14: =INDEX(Households!$B$2:$B$17,MATCH(D14,Households!$A$2:$A$17,0)) -> 5 | F14: 4 | G14: 0.33333333 | H14: 0.36805556 | I14: =ROUND((H14-G14)*1440,0) -> 50 | J14: Rice, Dal, Vegetables | K14: Electric pressure cooker | L14: Solar | M14: Yes | N14: Yes | O14: No | Q14: No | T14: =ROUND(INDEX(Appliances!$C$2:$C$4,MATCH(K14,Appliances!$B$2:$B$4,0))*I14/60*Config!$B$10,2) -> 0.5 | U14: =ROUND(I14/F14,1) -> 12.5 | V14: =IF(F14<=3,"1-3",IF(F14<=5,"4-5",IF(F14<=7,"6-7","8+"))) -> 4-5
A15: CS-0014 | B15: 46282 | C15: SL-0015 | D15: HH-15 | E15: =INDEX(Households!$B$2:$B$17,MATCH(D15,Households!$A$2:$A$17,0)) -> 6 | F15: 5 | G15: 0.42013889 | H15: 0.44791667 | I15: =ROUND((H15-G15)*1440,0) -> 40 | J15: Khichuri | K15: Electric pressure cooker | L15: Solar | M15: Yes | N15: No | O15: No | Q15: No | T15: =ROUND(INDEX(Appliances!$C$2:$C$4,MATCH(K15,Appliances!$B$2:$B$4,0))*I15/60*Config!$B$10,2) -> 0.4 | U15: =ROUND(I15/F15,1) -> 8 | V15: =IF(F15<=3,"1-3",IF(F15<=5,"4-5",IF(F15<=7,"6-7","8+"))) -> 4-5
A16: CS-0015 | B16: 46282 | C16: SL-0016 | D16: HH-16 | E16: =INDEX(Households!$B$2:$B$17,MATCH(D16,Households!$A$2:$A$17,0)) -> 3 | F16: 3 | G16: 0.50694444 | H16: 0.54513889 | I16: =ROUND((H16-G16)*1440,0) -> 55 | J16: Rice, Dal, Vegetables | K16: Electric pressure cooker | L16: Solar | M16: Yes | N16: Yes | O16: No | Q16: No | T16: =ROUND(INDEX(Appliances!$C$2:$C$4,MATCH(K16,Appliances!$B$2:$B$4,0))*I16/60*Config!$B$10,2) -> 0.55 | U16: =ROUND(I16/F16,1) -> 18.3 | V16: =IF(F16<=3,"1-3",IF(F16<=5,"4-5",IF(F16<=7,"6-7","8+"))) -> 1-3
A17: CS-0016 | B17: 46282 | C17: SL-0017 | D17: HH-09 | E17: =INDEX(Households!$B$2:$B$17,MATCH(D17,Households!$A$2:$A$17,0)) -> 6 | F17: 6 | G17: 0.59027778 | H17: 0.63194444 | I17: =ROUND((H17-G17)*1440,0) -> 60 | J17: Rice, Dal, Vegetables | K17: Electric pressure cooker | L17: Solar | M17: Yes | N17: Yes | O17: No | Q17: No | T17: =ROUND(INDEX(Appliances!$C$2:$C$4,MATCH(K17,Appliances!$B$2:$B$4,0))*I17/60*Config!$B$10,2) -> 0.6 | U17: =ROUND(I17/F17,1) -> 10 | V17: =IF(F17<=3,"1-3",IF(F17<=5,"4-5",IF(F17<=7,"6-7","8+"))) -> 6-7
A18: CS-0017 | B18: 46282 | C18: SL-0018 | D18: HH-02 | E18: =INDEX(Households!$B$2:$B$17,MATCH(D18,Households!$A$2:$A$17,0)) -> 6 | F18: 6 | G18: 0.69444444 | H18: 0.73958333 | I18: =ROUND((H18-G18)*1440,0) -> 65 | J18: Rice, Dal, Fish | K18: Electric pressure cooker | L18: Battery | M18: Yes | N18: Yes | O18: No | Q18: No | T18: =ROUND(INDEX(Appliances!$C$2:$C$4,MATCH(K18,Appliances!$B$2:$B$4,0))*I18/60*Config!$B$10,2) -> 0.65 | U18: =ROUND(I18/F18,1) -> 10.8 | V18: =IF(F18<=3,"1-3",IF(F18<=5,"4-5",IF(F18<=7,"6-7","8+"))) -> 6-7
A19: CS-0018 | B19: 46283 | C19: SL-0019 | D19: HH-03 | E19: =INDEX(Households!$B$2:$B$17,MATCH(D19,Households!$A$2:$A$17,0)) -> 3 | F19: 3 | G19: 0.25347222 | H19: 0.33333333 | I19: =ROUND((H19-G19)*1440,0) -> 115 | J19: Rice, Dal | K19: Electric pressure cooker | L19: Battery | M19: Yes | N19: Yes | O19: No | Q19: Yes | R19: Appliance fault | S19: Cooker stopped twice and was restarted | T19: =ROUND(INDEX(Appliances!$C$2:$C$4,MATCH(K19,Appliances!$B$2:$B$4,0))*I19/60*Config!$B$10,2) -> 1.15 | U19: =ROUND(I19/F19,1) -> 38.3 | V19: =IF(F19<=3,"1-3",IF(F19<=5,"4-5",IF(F19<=7,"6-7","8+"))) -> 1-3
A20: CS-0019 | B20: 46283 | C20: SL-0020 | D20: HH-04 | E20: =INDEX(Households!$B$2:$B$17,MATCH(D20,Households!$A$2:$A$17,0)) -> 5 | F20: 5 | G20: 0.34027778 | H20: 0.39236111 | I20: =ROUND((H20-G20)*1440,0) -> 75 | J20: Rice, Curry | K20: Induction cooktop | L20: Solar | M20: Yes | N20: No | O20: No | Q20: No | T20: =ROUND(INDEX(Appliances!$C$2:$C$4,MATCH(K20,Appliances!$B$2:$B$4,0))*I20/60*Config!$B$10,2) -> 1.5 | U20: =ROUND(I20/F20,1) -> 15 | V20: =IF(F20<=3,"1-3",IF(F20<=5,"4-5",IF(F20<=7,"6-7","8+"))) -> 4-5
A21: CS-0020 | B21: 46283 | C21: SL-0021 | D21: HH-05 | E21: =INDEX(Households!$B$2:$B$17,MATCH(D21,Households!$A$2:$A$17,0)) -> 7 | F21: 7 | G21: 0.43055556 | H21: 0.46527778 | I21: =ROUND((H21-G21)*1440,0) -> 50 | J21: Rice, Dal | K21: Electric pressure cooker | L21: Solar | M21: Yes | N21: Yes | O21: Yes | P21: No free slot | Q21: No | T21: =ROUND(INDEX(Appliances!$C$2:$C$4,MATCH(K21,Appliances!$B$2:$B$4,0))*I21/60*Config!$B$10,2) -> 0.5 | U21: =ROUND(I21/F21,1) -> 7.1 | V21: =IF(F21<=3,"1-3",IF(F21<=5,"4-5",IF(F21<=7,"6-7","8+"))) -> 6-7
A22: CS-0021 | B22: 46283 | C22: SL-0022 | D22: HH-06 | E22: =INDEX(Households!$B$2:$B$17,MATCH(D22,Households!$A$2:$A$17,0)) -> 5 | F22: 4 | G22: 0.50694444 | H22: 0.55208333 | I22: =ROUND((H22-G22)*1440,0) -> 65 | J22: Rice, Dal, Vegetables | K22: Electric pressure cooker | L22: Solar | M22: Yes | N22: Yes | O22: No | Q22: No | T22: =ROUND(INDEX(Appliances!$C$2:$C$4,MATCH(K22,Appliances!$B$2:$B$4,0))*I22/60*Config!$B$10,2) -> 0.65 | U22: =ROUND(I22/F22,1) -> 16.3 | V22: =IF(F22<=3,"1-3",IF(F22<=5,"4-5",IF(F22<=7,"6-7","8+"))) -> 4-5
A23: CS-0022 | B23: 46283 | C23: SL-0023 | D23: HH-07 | E23: =INDEX(Households!$B$2:$B$17,MATCH(D23,Households!$A$2:$A$17,0)) -> 8 | F23: 8 | G23: 0.59027778 | H23: 0.64930556 | I23: =ROUND((H23-G23)*1440,0) -> 85 | J23: Rice, Curry | K23: Induction cooktop | L23: Solar | M23: Yes | N23: Yes | O23: Yes | P23: No free slot | Q23: No | T23: =ROUND(INDEX(Appliances!$C$2:$C$4,MATCH(K23,Appliances!$B$2:$B$4,0))*I23/60*Config!$B$10,2) -> 1.7 | U23: =ROUND(I23/F23,1) -> 10.6 | V23: =IF(F23<=3,"1-3",IF(F23<=5,"4-5",IF(F23<=7,"6-7","8+"))) -> 8+
A24: CS-0023 | B24: 46283 | C24: SL-0024 | D24: HH-08 | E24: =INDEX(Households!$B$2:$B$17,MATCH(D24,Households!$A$2:$A$17,0)) -> 4 | F24: 4 | G24: 0.69097222 | H24: 0.73263889 | I24: =ROUND((H24-G24)*1440,0) -> 60 | J24: Rice, Fish | K24: Induction cooktop | L24: Battery | M24: Yes | N24: Yes | O24: No | Q24: No | T24: =ROUND(INDEX(Appliances!$C$2:$C$4,MATCH(K24,Appliances!$B$2:$B$4,0))*I24/60*Config!$B$10,2) -> 1.2 | U24: =ROUND(I24/F24,1) -> 15 | V24: =IF(F24<=3,"1-3",IF(F24<=5,"4-5",IF(F24<=7,"6-7","8+"))) -> 4-5
A25: CS-0024 | B25: 46284 | C25: SL-0025 | D25: HH-09 | E25: =INDEX(Households!$B$2:$B$17,MATCH(D25,Households!$A$2:$A$17,0)) -> 6 | F25: 5 | G25: 0.26736111 | H25: 0.3125 | I25: =ROUND((H25-G25)*1440,0) -> 65 | J25: Rice, Curry | K25: Induction cooktop | L25: Battery | M25: Yes | N25: Yes | O25: Yes | P25: Late start | Q25: No | S25: Previous household finished late | T25: =ROUND(INDEX(Appliances!$C$2:$C$4,MATCH(K25,Appliances!$B$2:$B$4,0))*I25/60*Config!$B$10,2) -> 1.3 | U25: =ROUND(I25/F25,1) -> 13 | V25: =IF(F25<=3,"1-3",IF(F25<=5,"4-5",IF(F25<=7,"6-7","8+"))) -> 4-5
A26: CS-0025 | B26: 46284 | C26: SL-0026 | D26: HH-10 | E26: =INDEX(Households!$B$2:$B$17,MATCH(D26,Households!$A$2:$A$17,0)) -> 3 | F26: 3 | G26: 0.33680556 | H26: 0.35763889 | I26: =ROUND((H26-G26)*1440,0) -> 30 | J26: Khichuri | K26: Electric pressure cooker | L26: Solar | M26: Yes | N26: Yes | O26: No | Q26: No | T26: =ROUND(INDEX(Appliances!$C$2:$C$4,MATCH(K26,Appliances!$B$2:$B$4,0))*I26/60*Config!$B$10,2) -> 0.3 | U26: =ROUND(I26/F26,1) -> 10 | V26: =IF(F26<=3,"1-3",IF(F26<=5,"4-5",IF(F26<=7,"6-7","8+"))) -> 1-3
A27: CS-0026 | B27: 46284 | C27: SL-0027 | D27: HH-11 | E27: =INDEX(Households!$B$2:$B$17,MATCH(D27,Households!$A$2:$A$17,0)) -> 5 | F27: 5 | G27: 0.42361111 | H27: 0.48263889 | I27: =ROUND((H27-G27)*1440,0) -> 85 | J27: Rice, Meat | K27: Electric pressure cooker | L27: Solar | M27: Yes | N27: Yes | O27: No | Q27: Yes | R27: Power cut | T27: =ROUND(INDEX(Appliances!$C$2:$C$4,MATCH(K27,Appliances!$B$2:$B$4,0))*I27/60*Config!$B$10,2) -> 0.85 | U27: =ROUND(I27/F27,1) -> 17 | V27: =IF(F27<=3,"1-3",IF(F27<=5,"4-5",IF(F27<=7,"6-7","8+"))) -> 4-5
A28: CS-0027 | B28: 46284 | C28: SL-0028 | D28: HH-12 | E28: =INDEX(Households!$B$2:$B$17,MATCH(D28,Households!$A$2:$A$17,0)) -> 7 | F28: 7 | G28: 0.50347222 | H28: 0.54166667 | I28: =ROUND((H28-G28)*1440,0) -> 55 | J28: Rice, Dal | K28: Electric pressure cooker | L28: Solar | M28: Yes | N28: No | O28: No | Q28: No | T28: =ROUND(INDEX(Appliances!$C$2:$C$4,MATCH(K28,Appliances!$B$2:$B$4,0))*I28/60*Config!$B$10,2) -> 0.55 | U28: =ROUND(I28/F28,1) -> 7.9 | V28: =IF(F28<=3,"1-3",IF(F28<=5,"4-5",IF(F28<=7,"6-7","8+"))) -> 6-7
A29: CS-0028 | B29: 46284 | C29: SL-0029 | D29: HH-13 | E29: =INDEX(Households!$B$2:$B$17,MATCH(D29,Households!$A$2:$A$17,0)) -> 4 | F29: 4 | G29: 0.58680556 | H29: 0.61805556 | I29: =ROUND((H29-G29)*1440,0) -> 45 | J29: Rice, Dal | K29: Electric pressure cooker | L29: Solar | M29: Yes | N29: Yes | O29: No | Q29: No | T29: =ROUND(INDEX(Appliances!$C$2:$C$4,MATCH(K29,Appliances!$B$2:$B$4,0))*I29/60*Config!$B$10,2) -> 0.45 | U29: =ROUND(I29/F29,1) -> 11.3 | V29: =IF(F29<=3,"1-3",IF(F29<=5,"4-5",IF(F29<=7,"6-7","8+"))) -> 4-5
A30: CS-0029 | B30: 46284 | C30: SL-0030 | D30: HH-14 | E30: =INDEX(Households!$B$2:$B$17,MATCH(D30,Households!$A$2:$A$17,0)) -> 5 | F30: 5 | G30: 0.6875 | H30: 0.73611111 | I30: =ROUND((H30-G30)*1440,0) -> 70 | J30: Rice, Dal, Vegetables | K30: Electric pressure cooker | L30: Battery | M30: Yes | N30: Yes | O30: No | Q30: No | T30: =ROUND(INDEX(Appliances!$C$2:$C$4,MATCH(K30,Appliances!$B$2:$B$4,0))*I30/60*Config!$B$10,2) -> 0.7 | U30: =ROUND(I30/F30,1) -> 14 | V30: =IF(F30<=3,"1-3",IF(F30<=5,"4-5",IF(F30<=7,"6-7","8+"))) -> 4-5
A31: CS-0030 | B31: 46285 | C31: SL-0031 | D31: HH-15 | E31: =INDEX(Households!$B$2:$B$17,MATCH(D31,Households!$A$2:$A$17,0)) -> 6 | F31: 6 | G31: 0.25347222 | H31: 0.3125 | I31: =ROUND((H31-G31)*1440,0) -> 85 | J31: Rice, Curry | K31: Induction cooktop | L31: Battery | M31: Yes | N31: No | O31: No | Q31: No | T31: =ROUND(INDEX(Appliances!$C$2:$C$4,MATCH(K31,Appliances!$B$2:$B$4,0))*I31/60*Config!$B$10,2) -> 1.7 | U31: =ROUND(I31/F31,1) -> 14.2 | V31: =IF(F31<=3,"1-3",IF(F31<=5,"4-5",IF(F31<=7,"6-7","8+"))) -> 6-7
A32: CS-0031 | B32: 46285 | C32: SL-0032 | D32: HH-16 | E32: =INDEX(Households!$B$2:$B$17,MATCH(D32,Households!$A$2:$A$17,0)) -> 3 | F32: 3 | G32: 0.33333333 | H32: 0.375 | I32: =ROUND((H32-G32)*1440,0) -> 60 | J32: Rice, Dal, Vegetables | K32: Electric pressure cooker | L32: Solar | M32: Yes | N32: Yes | O32: No | Q32: No | T32: =ROUND(INDEX(Appliances!$C$2:$C$4,MATCH(K32,Appliances!$B$2:$B$4,0))*I32/60*Config!$B$10,2) -> 0.6 | U32: =ROUND(I32/F32,1) -> 20 | V32: =IF(F32<=3,"1-3",IF(F32<=5,"4-5",IF(F32<=7,"6-7","8+"))) -> 1-3
A33: CS-0032 | B33: 46285 | C33: SL-0033 | D33: HH-01 | E33: =INDEX(Households!$B$2:$B$17,MATCH(D33,Households!$A$2:$A$17,0)) -> 4 | F33: 3 | G33: 0.41666667 | H33: 0.45486111 | I33: =ROUND((H33-G33)*1440,0) -> 55 | J33: Rice, Dal, Vegetables | K33: Electric pressure cooker | L33: Solar | M33: Yes | N33: Yes | O33: No | Q33: No | T33: =ROUND(INDEX(Appliances!$C$2:$C$4,MATCH(K33,Appliances!$B$2:$B$4,0))*I33/60*Config!$B$10,2) -> 0.55 | U33: =ROUND(I33/F33,1) -> 18.3 | V33: =IF(F33<=3,"1-3",IF(F33<=5,"4-5",IF(F33<=7,"6-7","8+"))) -> 1-3
A34: CS-0033 | B34: 46285 | C34: SL-0034 | D34: HH-02 | E34: =INDEX(Households!$B$2:$B$17,MATCH(D34,Households!$A$2:$A$17,0)) -> 6 | F34: 6 | G34: 0.5 | H34: 0.53819444 | I34: =ROUND((H34-G34)*1440,0) -> 55 | J34: Rice, Dal, Vegetables | K34: Electric pressure cooker | L34: Solar | M34: Yes | N34: Yes | O34: No | Q34: No | T34: =ROUND(INDEX(Appliances!$C$2:$C$4,MATCH(K34,Appliances!$B$2:$B$4,0))*I34/60*Config!$B$10,2) -> 0.55 | U34: =ROUND(I34/F34,1) -> 9.2 | V34: =IF(F34<=3,"1-3",IF(F34<=5,"4-5",IF(F34<=7,"6-7","8+"))) -> 6-7
A35: CS-0034 | B35: 46285 | C35: SL-0035 | D35: HH-03 | E35: =INDEX(Households!$B$2:$B$17,MATCH(D35,Households!$A$2:$A$17,0)) -> 3 | F35: 3 | G35: 0.58680556 | H35: 0.625 | I35: =ROUND((H35-G35)*1440,0) -> 55 | J35: Rice, Dal, Fish | K35: Electric pressure cooker | L35: Solar | M35: Yes | N35: Yes | O35: No | Q35: No | T35: =ROUND(INDEX(Appliances!$C$2:$C$4,MATCH(K35,Appliances!$B$2:$B$4,0))*I35/60*Config!$B$10,2) -> 0.55 | U35: =ROUND(I35/F35,1) -> 18.3 | V35: =IF(F35<=3,"1-3",IF(F35<=5,"4-5",IF(F35<=7,"6-7","8+"))) -> 1-3
A36: CS-0035 | B36: 46285 | C36: SL-0036 | D36: HH-06 | E36: =INDEX(Households!$B$2:$B$17,MATCH(D36,Households!$A$2:$A$17,0)) -> 5 | F36: 5 | G36: 0.69444444 | H36: 0.73611111 | I36: =ROUND((H36-G36)*1440,0) -> 60 | J36: Rice, Meat | K36: Electric pressure cooker | L36: Battery | M36: Yes | N36: Yes | O36: No | Q36: No | T36: =ROUND(INDEX(Appliances!$C$2:$C$4,MATCH(K36,Appliances!$B$2:$B$4,0))*I36/60*Config!$B$10,2) -> 0.6 | U36: =ROUND(I36/F36,1) -> 12 | V36: =IF(F36<=3,"1-3",IF(F36<=5,"4-5",IF(F36<=7,"6-7","8+"))) -> 4-5
A37: CS-0036 | B37: 46286 | C37: SL-0037 | D37: HH-05 | E37: =INDEX(Households!$B$2:$B$17,MATCH(D37,Households!$A$2:$A$17,0)) -> 7 | F37: 7 | G37: 0.25694444 | H37: 0.3125 | I37: =ROUND((H37-G37)*1440,0) -> 80 | J37: Rice, Curry | K37: Induction cooktop | L37: Battery | M37: Yes | N37: Yes | O37: No | Q37: No | T37: =ROUND(INDEX(Appliances!$C$2:$C$4,MATCH(K37,Appliances!$B$2:$B$4,0))*I37/60*Config!$B$10,2) -> 1.6 | U37: =ROUND(I37/F37,1) -> 11.4 | V37: =IF(F37<=3,"1-3",IF(F37<=5,"4-5",IF(F37<=7,"6-7","8+"))) -> 6-7
A38: CS-0037 | B38: 46286 | C38: SL-0038 | D38: HH-06 | E38: =INDEX(Households!$B$2:$B$17,MATCH(D38,Households!$A$2:$A$17,0)) -> 5 | F38: 5 | G38: 0.34027778 | H38: 0.37152778 | I38: =ROUND((H38-G38)*1440,0) -> 45 | J38: Rice | K38: Rice cooker | L38: Solar | M38: Yes | N38: Yes | O38: No | Q38: No | T38: =ROUND(INDEX(Appliances!$C$2:$C$4,MATCH(K38,Appliances!$B$2:$B$4,0))*I38/60*Config!$B$10,2) -> 0.32 | U38: =ROUND(I38/F38,1) -> 9 | V38: =IF(F38<=3,"1-3",IF(F38<=5,"4-5",IF(F38<=7,"6-7","8+"))) -> 4-5
A39: CS-0038 | B39: 46286 | C39: SL-0039 | D39: HH-07 | E39: =INDEX(Households!$B$2:$B$17,MATCH(D39,Households!$A$2:$A$17,0)) -> 8 | F39: 7 | G39: 0.42361111 | H39: 0.47916667 | I39: =ROUND((H39-G39)*1440,0) -> 80 | J39: Rice, Fish | K39: Induction cooktop | L39: Solar | M39: Yes | N39: Yes | O39: No | Q39: Yes | R39: Other | T39: =ROUND(INDEX(Appliances!$C$2:$C$4,MATCH(K39,Appliances!$B$2:$B$4,0))*I39/60*Config!$B$10,2) -> 1.6 | U39: =ROUND(I39/F39,1) -> 11.4 | V39: =IF(F39<=3,"1-3",IF(F39<=5,"4-5",IF(F39<=7,"6-7","8+"))) -> 6-7
A40: CS-0039 | B40: 46286 | C40: SL-0040 | D40: HH-08 | E40: =INDEX(Households!$B$2:$B$17,MATCH(D40,Households!$A$2:$A$17,0)) -> 4 | F40: 3 | G40: 0.50347222 | H40: 0.53472222 | I40: =ROUND((H40-G40)*1440,0) -> 45 | J40: Rice, Dal | K40: Electric pressure cooker | L40: Solar | M40: Yes | N40: Yes | O40: No | Q40: No | T40: =ROUND(INDEX(Appliances!$C$2:$C$4,MATCH(K40,Appliances!$B$2:$B$4,0))*I40/60*Config!$B$10,2) -> 0.45 | U40: =ROUND(I40/F40,1) -> 15 | V40: =IF(F40<=3,"1-3",IF(F40<=5,"4-5",IF(F40<=7,"6-7","8+"))) -> 1-3
...

Sheet Session_Dishes
A1: Session ID | B1: Dish
A2: CS-0001 | B2: Rice
A3: CS-0001 | B3: Dal
A4: CS-0002 | B4: Rice
A5: CS-0002 | B5: Vegetables
A6: CS-0003 | B6: Rice
A7: CS-0003 | B7: Dal
A8: CS-0003 | B8: Fish
A9: CS-0004 | B9: Rice
A10: CS-0004 | B10: Meat
A11: CS-0005 | B11: Rice
A12: CS-0005 | B12: Dal
... A164: CS-0079 | B164: Dal

Sheet Daily_Technical
A1: Date | B1: Weather | C1: Solar produced (kWh) | D1: Morning battery % | E1: Evening battery % | F1: System operational | G1: Faults | H1: Downtime (h) | I1: Safety incident | J1: Safety note | K1: Energy consumed, kWh (calc) | L1: Expected solar, kWh (calc) | M1: Efficiency (calc) | N1: Battery change, kWh (calc) | O1: Wasted energy, kWh (calc) | P1: Wasted share (calc) | Q1: Downtime loss, kWh (calc) | R1: Remarks
A2: 46280 | B2: Rainy | C2: 2.2 | D2: 62 | E2: 59 | F2: Yes | G2: 0 | H2: 0 | I2: No | K2: =SUMIFS(Cooking_Sessions!$T$2:$T$80,Cooking_Sessions!$B$2:$B$80,A2,Cooking_Sessions!$L$2:$L$80,"<>Generator") -> 2.3 | L2: =ROUND(Config!$B$3*Config!$B$6*INDEX(Weather_Factors!$B$2:$B$6,MATCH(B2,Weather_Factors!$A$2:$A$6,0))*Config!$B$5,2) -> 2.7 | M2: =IFERROR(C2/L2,0) -> 0.81481481 | N2: =ROUND((E2-D2)/100*Config!$B$4,2) -> -0.3 | O2: =ROUND(C2-K2-N2,2) -> 0.2 | P2: =IFERROR(O2/C2,0) -> 0.090909091 | Q2: =ROUND(L2/Config!$B$11*H2,2) -> 0
A3: 46281 | B3: Cloudy | C3: 4 | D3: 55 | E3: 65 | F3: Yes | G3: 2 | H3: 0.5 | I3: No | K3: =SUMIFS(Cooking_Sessions!$T$2:$T$80,Cooking_Sessions!$B$2:$B$80,A3,Cooking_Sessions!$L$2:$L$80,"<>Generator") -> 2.6 | L3: =ROUND(Config!$B$3*Config!$B$6*INDEX(Weather_Factors!$B$2:$B$6,MATCH(B3,Weather_Factors!$A$2:$A$6,0))*Config!$B$5,2) -> 4.73 | M3: =IFERROR(C3/L3,0) -> 0.84566596 | N3: =ROUND((E3-D3)/100*Config!$B$4,2) -> 1 | O3: =ROUND(C3-K3-N3,2) -> 0.4 | P3: =IFERROR(O3/C3,0) -> 0.1 | Q3: =ROUND(L3/Config!$B$11*H3,2) -> 0.24 | R3: Inverter trip, restarted
A4: 46282 | B4: Partly cloudy | C4: 8.2 | D4: 61 | E4: 96 | F4: Yes | G4: 0 | H4: 0 | I4: No | K4: =SUMIFS(Cooking_Sessions!$T$2:$T$80,Cooking_Sessions!$B$2:$B$80,A4,Cooking_Sessions!$L$2:$L$80,"<>Generator") -> 3.9 | L4: =ROUND(Config!$B$3*Config!$B$6*INDEX(Weather_Factors!$B$2:$B$6,MATCH(B4,Weather_Factors!$A$2:$A$6,0))*Config!$B$5,2) -> 8.78 | M4: =IFERROR(C4/L4,0) -> 0.93394077 | N4: =ROUND((E4-D4)/100*Config!$B$4,2) -> 3.5 | O4: =ROUND(C4-K4-N4,2) -> 0.8 | P4: =IFERROR(O4/C4,0) -> 0.097560976 | Q4: =ROUND(L4/Config!$B$11*H4,2) -> 0
A5: 46283 | B5: Sunny | C5: 11.4 | D5: 92 | E5: 100 | F5: Yes | G5: 0 | H5: 0 | I5: No | K5: =SUMIFS(Cooking_Sessions!$T$2:$T$80,Cooking_Sessions!$B$2:$B$80,A5,Cooking_Sessions!$L$2:$L$80,"<>Generator") -> 6.7 | L5: =ROUND(Config!$B$3*Config!$B$6*INDEX(Weather_Factors!$B$2:$B$6,MATCH(B5,Weather_Factors!$A$2:$A$6,0))*Config!$B$5,2) -> 13.5 | M5: =IFERROR(C5/L5,0) -> 0.84444444 | N5: =ROUND((E5-D5)/100*Config!$B$4,2) -> 0.8 | O5: =ROUND(C5-K5-N5,2) -> 3.9 | P5: =IFERROR(O5/C5,0) -> 0.34210526 | Q5: =ROUND(L5/Config!$B$11*H5,2) -> 0
A6: 46284 | B6: Sunny | C6: 12.6 | D6: 96 | E6: 100 | F6: Yes | G6: 0 | H6: 0 | I6: No | K6: =SUMIFS(Cooking_Sessions!$T$2:$T$80,Cooking_Sessions!$B$2:$B$80,A6,Cooking_Sessions!$L$2:$L$80,"<>Generator") -> 4.15 | L6: =ROUND(Config!$B$3*Config!$B$6*INDEX(Weather_Factors!$B$2:$B$6,MATCH(B6,Weather_Factors!$A$2:$A$6,0))*Config!$B$5,2) -> 13.5 | M6: =IFERROR(C6/L6,0) -> 0.93333333 | N6: =ROUND((E6-D6)/100*Config!$B$4,2) -> 0.4 | O6: =ROUND(C6-K6-N6,2) -> 8.05 | P6: =IFERROR(O6/C6,0) -> 0.63888889 | Q6: =ROUND(L6/Config!$B$11*H6,2) -> 0
A7: 46285 | B7: Partly cloudy | C7: 7.4 | D7: 96 | E7: 100 | F7: Yes | G7: 0 | H7: 0 | I7: No | K7: =SUMIFS(Cooking_Sessions!$T$2:$T$80,Cooking_Sessions!$B$2:$B$80,A7,Cooking_Sessions!$L$2:$L$80,"<>Generator") -> 4.55 | L7: =ROUND(Config!$B$3*Config!$B$6*INDEX(Weather_Factors!$B$2:$B$6,MATCH(B7,Weather_Factors!$A$2:$A$6,0))*Config!$B$5,2) -> 8.78 | M7: =IFERROR(C7/L7,0) -> 0.8428246 | N7: =ROUND((E7-D7)/100*Config!$B$4,2) -> 0.4 | O7: =ROUND(C7-K7-N7,2) -> 2.45 | P7: =IFERROR(O7/C7,0) -> 0.33108108 | Q7: =ROUND(L7/Config!$B$11*H7,2) -> 0
A8: 46286 | B8: Cloudy | C8: 4.3 | D8: 96 | E8: 95 | F8: Yes | G8: 0 | H8: 0 | I8: No | K8: =SUMIFS(Cooking_Sessions!$T$2:$T$80,Cooking_Sessions!$B$2:$B$80,A8,Cooking_Sessions!$L$2:$L$80,"<>Generator") -> 3.97 | L8: =ROUND(Config!$B$3*Config!$B$6*INDEX(Weather_Factors!$B$2:$B$6,MATCH(B8,Weather_Factors!$A$2:$A$6,0))*Config!$B$5,2) -> 4.73 | M8: =IFERROR(C8/L8,0) -> 0.90909091 | N8: =ROUND((E8-D8)/100*Config!$B$4,2) -> -0.1 | O8: =ROUND(C8-K8-N8,2) -> 0.43 | P8: =IFERROR(O8/C8,0) -> 0.1 | Q8: =ROUND(L8/Config!$B$11*H8,2) -> 0
A9: 46287 | B9: Stormy | C9: 1.1 | D9: 91 | E9: 88 | F9: No | G9: 2 | H9: 3.5 | I9: No | K9: =SUMIFS(Cooking_Sessions!$T$2:$T$80,Cooking_Sessions!$B$2:$B$80,A9,Cooking_Sessions!$L$2:$L$80,"<>Generator") -> 1.3 | L9: =ROUND(Config!$B$3*Config!$B$6*INDEX(Weather_Factors!$B$2:$B$6,MATCH(B9,Weather_Factors!$A$2:$A$6,0))*Config!$B$5,2) -> 1.35 | M9: =IFERROR(C9/L9,0) -> 0.81481481 | N9: =ROUND((E9-D9)/100*Config!$B$4,2) -> -0.3 | O9: =ROUND(C9-K9-N9,2) -> 0.1 | P9: =IFERROR(O9/C9,0) -> 0.090909091 | Q9: =ROUND(L9/Config!$B$11*H9,2) -> 0.47 | R9: Storm: system off for part of the day
A10: 46288 | B10: Rainy | C10: 2.6 | D10: 84 | E10: 83 | F10: Yes | G10: 0 | H10: 0 | I10: No | K10: =SUMIFS(Cooking_Sessions!$T$2:$T$80,Cooking_Sessions!$B$2:$B$80,A10,Cooking_Sessions!$L$2:$L$80,"<>Generator") -> 2.4 | L10: =ROUND(Config!$B$3*Config!$B$6*INDEX(Weather_Factors!$B$2:$B$6,MATCH(B10,Weather_Factors!$A$2:$A$6,0))*Config!$B$5,2) -> 2.7 | M10: =IFERROR(C10/L10,0) -> 0.96296296 | N10: =ROUND((E10-D10)/100*Config!$B$4,2) -> -0.1 | O10: =ROUND(C10-K10-N10,2) -> 0.3 | P10: =IFERROR(O10/C10,0) -> 0.11538462 | Q10: =ROUND(L10/Config!$B$11*H10,2) -> 0
A11: 46289 | B11: Partly cloudy | C11: 5.7 | D11: 79 | E11: 70 | F11: Yes | G11: 0 | H11: 0 | I11: No | K11: =SUMIFS(Cooking_Sessions!$T$2:$T$80,Cooking_Sessions!$B$2:$B$80,A11,Cooking_Sessions!$L$2:$L$80,"<>Generator") -> 6 | L11: =ROUND(Config!$B$3*Config!$B$6*INDEX(Weather_Factors!$B$2:$B$6,MATCH(B11,Weather_Factors!$A$2:$A$6,0))*Config!$B$5,2) -> 8.78 | M11: =IFERROR(C11/L11,0) -> 0.64920273 | N11: =ROUND((E11-D11)/100*Config!$B$4,2) -> -0.9 | O11: =ROUND(C11-K11-N11,2) -> 0.6 | P11: =IFERROR(O11/C11,0) -> 0.10526316 | Q11: =ROUND(L11/Config!$B$11*H11,2) -> 0 | R11: Panels dusty; cleaned the next morning
A12: 46290 | B12: Sunny | C12: 11.8 | D12: 66 | E12: 100 | F12: Yes | G12: 0 | H12: 0 | I12: Yes | J12: Minor: loose cable found near battery cabinet and fixed | K12: =SUMIFS(Cooking_Sessions!$T$2:$T$80,Cooking_Sessions!$B$2:$B$80,A12,Cooking_Sessions!$L$2:$L$80,"<>Generator") -> 2.23 | L12: =ROUND(Config!$B$3*Config!$B$6*INDEX(Weather_Factors!$B$2:$B$6,MATCH(B12,Weather_Factors!$A$2:$A$6,0))*Config!$B$5,2) -> 13.5 | M12: =IFERROR(C12/L12,0) -> 0.87407407 | N12: =ROUND((E12-D12)/100*Config!$B$4,2) -> 3.4 | O12: =ROUND(C12-K12-N12,2) -> 6.17 | P12: =IFERROR(O12/C12,0) -> 0.52288136 | Q12: =ROUND(L12/Config!$B$11*H12,2) -> 0
A13: 46291 | B13: Sunny | C13: 13.1 | D13: 96 | E13: 100 | F13: Yes | G13: 0 | H13: 0 | I13: No | K13: =SUMIFS(Cooking_Sessions!$T$2:$T$80,Cooking_Sessions!$B$2:$B$80,A13,Cooking_Sessions!$L$2:$L$80,"<>Generator") -> 3.48 | L13: =ROUND(Config!$B$3*Config!$B$6*INDEX(Weather_Factors!$B$2:$B$6,MATCH(B13,Weather_Factors!$A$2:$A$6,0))*Config!$B$5,2) -> 13.5 | M13: =IFERROR(C13/L13,0) -> 0.97037037 | N13: =ROUND((E13-D13)/100*Config!$B$4,2) -> 0.4 | O13: =ROUND(C13-K13-N13,2) -> 9.22 | P13: =IFERROR(O13/C13,0) -> 0.70381679 | Q13: =ROUND(L13/Config!$B$11*H13,2) -> 0
A14: 46292 | B14: Partly cloudy | C14: 7.5 | D14: 96 | E14: 100 | F14: Yes | G14: 0 | H14: 0 | I14: No | K14: =SUMIFS(Cooking_Sessions!$T$2:$T$80,Cooking_Sessions!$B$2:$B$80,A14,Cooking_Sessions!$L$2:$L$80,"<>Generator") -> 4.7 | L14: =ROUND(Config!$B$3*Config!$B$6*INDEX(Weather_Factors!$B$2:$B$6,MATCH(B14,Weather_Factors!$A$2:$A$6,0))*Config!$B$5,2) -> 8.78 | M14: =IFERROR(C14/L14,0) -> 0.85421412 | N14: =ROUND((E14-D14)/100*Config!$B$4,2) -> 0.4 | O14: =ROUND(C14-K14-N14,2) -> 2.4 | P14: =IFERROR(O14/C14,0) -> 0.32 | Q14: =ROUND(L14/Config!$B$11*H14,2) -> 0
A15: 46293 | B15: Cloudy | C15: 4.2 | D15: 96 | E15: 85 | F15: Yes | G15: 0 | H15: 0 | I15: No | K15: =SUMIFS(Cooking_Sessions!$T$2:$T$80,Cooking_Sessions!$B$2:$B$80,A15,Cooking_Sessions!$L$2:$L$80,"<>Generator") -> 4.85 | L15: =ROUND(Config!$B$3*Config!$B$6*INDEX(Weather_Factors!$B$2:$B$6,MATCH(B15,Weather_Factors!$A$2:$A$6,0))*Config!$B$5,2) -> 4.73 | M15: =IFERROR(C15/L15,0) -> 0.88794926 | N15: =ROUND((E15-D15)/100*Config!$B$4,2) -> -1.1 | O15: =ROUND(C15-K15-N15,2) -> 0.45 | P15: =IFERROR(O15/C15,0) -> 0.10714286 | Q15: =ROUND(L15/Config!$B$11*H15,2) -> 0

Sheet Generator_Log
A1: Date | B1: Fuel at start (L) | C1: Re-fuel (L) | D1: Fuel at end (L) | E1: Running time (h) | F1: Maintenance required | G1: Maintenance type | H1: Remarks | I1: Fuel used, L (calc)
A2: 46280 | B2: 20 | C2: 0 | D2: 14.8 | E2: 4 | F2: No | I2: =ROUND(B2+C2-D2,1) -> 5.2
A3: 46281 | B3: 14.8 | C3: 0 | D3: 8.9 | E3: 4.5 | F3: No | I3: =ROUND(B3+C3-D3,1) -> 5.9
A4: 46286 | B4: 8.9 | C4: 15 | D4: 18 | E4: 4.5 | F4: No | I4: =ROUND(B4+C4-D4,1) -> 5.9
A5: 46287 | B5: 18 | C5: 0 | D5: 12.8 | E5: 4 | F5: Yes | G5: Oil change | H5: Done after 4 hours of running | I5: =ROUND(B5+C5-D5,1) -> 5.2
A6: 46288 | B6: 12.8 | C6: 0 | D6: 7.6 | E6: 4 | F6: No | I6: =ROUND(B6+C6-D6,1) -> 5.2
A7: 46293 | B7: 7.6 | C7: 15 | D7: 16.7 | E7: 4.5 | F7: No | I7: =ROUND(B7+C7-D7,1) -> 5.9

Sheet Monthly_Feedback
A1: Household | B1: Month | C1: Backup fuel used | D1: Backup fuel spend (BDT) | E1: Fuel reduction (1-5) | F1: Safety (1-5) | G1: Privacy (1-5) | H1: Waiting (1-5) | I1: Overall satisfaction (1-5) | J1: Cleanliness (1-5) | K1: Ease of cooking (1-5) | L1: Slot suitability (1-5) | M1: Time enough for family size | N1: Family members now | O1: Willing to continue | P1: Remarks
A2: HH-01 | B2: 2026-09 | C2: Yes | D2: 550 | E2: 3 | F2: 4 | G2: 3 | H2: 5 | I2: 4 | J2: 3 | K2: 3 | L2: 5 | M2: About right | N2: 4 | O2: Yes
A3: HH-02 | B3: 2026-09 | C3: Yes | D3: 600 | E3: 4 | F3: 5 | G3: 3 | H3: 3 | I3: 5 | J3: 3 | K3: 4 | L3: 2 | M3: Too short | N3: 6 | O3: Yes
A4: HH-03 | B4: 2026-09 | C4: Yes | D4: 250 | E4: 4 | F4: 4 | G4: 3 | H4: 5 | I4: 3 | J4: 5 | K4: 3 | L4: 4 | M4: About right | N4: 3 | O4: Yes
A5: HH-04 | B5: 2026-09 | C5: Yes | D5: 650 | E5: 3 | F5: 5 | G5: 5 | H5: 3 | I5: 4 | J5: 4 | K5: 5 | L5: 5 | M5: About right | N5: 5 | O5: Yes
A6: HH-05 | B6: 2026-09 | C6: Yes | D6: 550 | E6: 4 | F6: 4 | G6: 4 | H6: 2 | I6: 4 | J6: 5 | K6: 5 | L6: 3 | M6: About right | N6: 8 | O6: Yes | P6: Waiting is the main problem
A7: HH-06 | B7: 2026-09 | C7: Yes | D7: 600 | E7: 3 | F7: 4 | G7: 3 | H7: 3 | I7: 5 | J7: 4 | K7: 5 | L7: 3 | M7: About right | N7: 5 | O7: Yes
A8: HH-07 | B8: 2026-09 | C8: Yes | D8: 900 | E8: 3 | F8: 4 | G8: 4 | H8: 3 | I8: 5 | J8: 3 | K8: 4 | L8: 3 | M8: Too short | N8: 8 | O8: Yes | P8: Needs longer slot for big family
A9: HH-08 | B9: 2026-09 | C9: Yes | D9: 250 | E9: 4 | F9: 5 | G9: 3 | H9: 4 | I9: 3 | J9: 3 | K9: 3 | L9: 4 | M9: About right | N9: 4 | O9: Yes
A10: HH-09 | B10: 2026-09 | C10: Yes | D10: 700 | E10: 3 | F10: 4 | G10: 4 | H10: 5 | I10: 3 | J10: 4 | K10: 5 | L10: 5 | M10: About right | N10: 6 | O10: No
A11: HH-10 | B11: 2026-09 | C11: Yes | D11: 300 | E11: 3 | F11: 5 | G11: 4 | H11: 2 | I11: 4 | J11: 3 | K11: 4 | L11: 3 | M11: About right | N11: 3 | O11: Yes | P11: Waiting is the main problem
A12: HH-11 | B12: 2026-09 | C12: Yes | D12: 600 | E12: 3 | F12: 5 | G12: 3 | H12: 3 | I12: 3 | J12: 4 | K12: 4 | L12: 4 | M12: About right | N12: 5 | O12: Yes
A13: HH-12 | B13: 2026-09 | C13: Yes | D13: 850 | E13: 3 | F13: 4 | G13: 4 | H13: 3 | I13: 4 | J13: 5 | K13: 3 | L13: 4 | M13: Too short | N13: 7 | O13: Yes | P13: Needs longer slot for big family
A14: HH-13 | B14: 2026-09 | C14: Yes | D14: 350 | E14: 3 | F14: 4 | G14: 3 | H14: 3 | I14: 3 | J14: 4 | K14: 4 | L14: 5 | M14: About right | N14: 4 | O14: Yes
A15: HH-14 | B15: 2026-09 | C15: Yes | D15: 550 | E15: 3 | F15: 5 | G15: 3 | H15: 3 | I15: 4 | J15: 3 | K15: 5 | L15: 3 | M15: Too long | N15: 5 | O15: Yes
A16: HH-15 | B16: 2026-09 | C16: Yes | D16: 400 | E16: 4 | F16: 5 | G16: 4 | H16: 4 | I16: 4 | J16: 3 | K16: 5 | L16: 4 | M16: About right | N16: 6 | O16: No
A17: HH-16 | B17: 2026-09 | C17: Yes | D17: 200 | E17: 4 | F17: 4 | G17: 3 | H17: 5 | I17: 5 | J17: 4 | K17: 5 | L17: 3 | M17: About right | N17: 3 | O17: Yes

Sheet Audit_Log
A1: ID | B1: Time | C1: User | D1: Action | E1: Table | F1: Record | G1: Detail
A2: 1 | B2: 2026-09-16 08:12 | C2: field01 | D2: CREATE | E2: cooking_sessions | F2: CS-0001 | G2: Entry saved offline, synced 08:40
A3: 2 | B3: 2026-09-17 18:30 | C3: tech01 | D3: CREATE | E3: daily_technical | F3: 2026-09-17 | G3: Daily log submitted
A4: 3 | B4: 2026-09-18 09:05 | C4: admin01 | D4: UPDATE | E4: cooking_sessions | F4: CS-0023 | G4: End time corrected from 11:10 to 11:05 (reason: typing error)
A5: 4 | B5: 2026-09-19 07:50 | C5: admin01 | D5: UPDATE | E5: slots | F5: SL-0020 | G5: Rotation changed by administrator
A6: 5 | B6: 2026-09-22 19:10 | C6: tech01 | D6: CREATE | E6: daily_technical | F6: 2026-09-22 | G6: Stormy day: system off for 3.5 hours
A7: 6 | B7: 2026-09-25 17:45 | C7: tech01 | D7: CREATE | E7: daily_technical | F7: 2026-09-25 | G7: Safety incident recorded
A8: 7 | B8: 2026-09-28 20:00 | C8: admin01 | D8: EXPORT | E8: reports | F8: monthly | G8: Monthly report exported to Excel
A9: 8 | B9: 2026-09-28 20:15 | C9: viewer01 | D9: LOGIN | E9: users | F9: viewer01 | G9: Dashboard viewed
